[2025-03-23T13:26:23.095+0000] {taskinstance.py:1157} INFO - Dependencies all met for dep_context=non-requeueable deps ti=<TaskInstance: healthcare_claims_pipeline.create_database_tables manual__2025-03-23T13:26:09.691817+00:00 [queued]>
[2025-03-23T13:26:23.106+0000] {taskinstance.py:1157} INFO - Dependencies all met for dep_context=requeueable deps ti=<TaskInstance: healthcare_claims_pipeline.create_database_tables manual__2025-03-23T13:26:09.691817+00:00 [queued]>
[2025-03-23T13:26:23.106+0000] {taskinstance.py:1359} INFO - Starting attempt 1 of 2
[2025-03-23T13:26:23.122+0000] {taskinstance.py:1380} INFO - Executing <Task(PythonOperator): create_database_tables> on 2025-03-23 13:26:09.691817+00:00
[2025-03-23T13:26:23.129+0000] {standard_task_runner.py:57} INFO - Started process 258 to run task
[2025-03-23T13:26:23.133+0000] {standard_task_runner.py:84} INFO - Running: ['***', 'tasks', 'run', 'healthcare_claims_pipeline', 'create_database_tables', 'manual__2025-03-23T13:26:09.691817+00:00', '--job-id', '5', '--raw', '--subdir', 'DAGS_FOLDER/healthcare_claims_dag.py', '--cfg-path', '/tmp/tmplm64hdxd']
[2025-03-23T13:26:23.135+0000] {standard_task_runner.py:85} INFO - Job 5: Subtask create_database_tables
[2025-03-23T13:26:23.187+0000] {task_command.py:415} INFO - Running <TaskInstance: healthcare_claims_pipeline.create_database_tables manual__2025-03-23T13:26:09.691817+00:00 [running]> on host f14adedb7c2a
[2025-03-23T13:26:23.266+0000] {taskinstance.py:1660} INFO - Exporting env vars: AIRFLOW_CTX_DAG_OWNER='***' AIRFLOW_CTX_DAG_ID='healthcare_claims_pipeline' AIRFLOW_CTX_TASK_ID='create_database_tables' AIRFLOW_CTX_EXECUTION_DATE='2025-03-23T13:26:09.691817+00:00' AIRFLOW_CTX_TRY_NUMBER='1' AIRFLOW_CTX_DAG_RUN_ID='manual__2025-03-23T13:26:09.691817+00:00'
[2025-03-23T13:26:23.284+0000] {taskinstance.py:1935} ERROR - Task failed with exception
Traceback (most recent call last):
  File "/home/airflow/.local/lib/python3.8/site-packages/airflow/operators/python.py", line 192, in execute
    return_value = self.execute_callable()
  File "/home/airflow/.local/lib/python3.8/site-packages/airflow/operators/python.py", line 209, in execute_callable
    return self.python_callable(*self.op_args, **self.op_kwargs)
  File "/opt/airflow/dags/healthcare_claims_dag.py", line 200, in create_database_tables
    conn = pg_hook.get_conn()
  File "/home/airflow/.local/lib/python3.8/site-packages/airflow/providers/postgres/hooks/postgres.py", line 124, in get_conn
    conn = deepcopy(self.connection or self.get_connection(conn_id))
  File "/home/airflow/.local/lib/python3.8/site-packages/airflow/hooks/base.py", line 72, in get_connection
    conn = Connection.get_connection_from_secrets(conn_id)
  File "/home/airflow/.local/lib/python3.8/site-packages/airflow/models/connection.py", line 477, in get_connection_from_secrets
    raise AirflowNotFoundException(f"The conn_id `{conn_id}` isn't defined")
airflow.exceptions.AirflowNotFoundException: The conn_id `postgres_default` isn't defined
[2025-03-23T13:26:23.288+0000] {taskinstance.py:1398} INFO - Marking task as UP_FOR_RETRY. dag_id=healthcare_claims_pipeline, task_id=create_database_tables, execution_date=20250323T132609, start_date=20250323T132623, end_date=20250323T132623
[2025-03-23T13:26:23.302+0000] {standard_task_runner.py:104} ERROR - Failed to execute job 5 for task create_database_tables (The conn_id `postgres_default` isn't defined; 258)
[2025-03-23T13:26:23.345+0000] {local_task_job_runner.py:228} INFO - Task exited with return code 1
[2025-03-23T13:26:23.374+0000] {taskinstance.py:2776} INFO - 0 downstream tasks scheduled from follow-on schedule check
